Workbook

Sheet report
A1: Наименование | B1: Регистрационный номер | C1: Статус | D1: Код налогоплательщика | E1: Регион регистрации | F1: Организационно-правовая форма | G1: 2017, Среднесписочная численность работников | H1: 2018, Среднесписочная численность работников | I1: 2017, Всего поступило средств, RUB | J1: 2018, Всего поступило средств, RUB | K1: 2017, Всего использовано средств, RUB | L1: 2018, Всего использовано средств, RUB
A2: 1ПОМОГАЕТ, БФ | B2: 1167700056347 | C2: Действующая | D2: 9718005523 | E2: Москва | F2: Благотворительные фонды | G2: 0 - 5 | I2: 1533000 | J2: 3635000 | K2: 1458000 | L2: 2559000
A3: 5541 ДОБРО, БФ | B3: 1147799011612 | C3: Действующая | D3: 7743111095 | E3: Москва | F3: Благотворительные фонды | G3: 11 - 15 | H3: 51 - 100 | I3: 754602000 | J3: 248596000 | K3: 641697000 | L3: 408668000
A4: А.УСМАНОВА, ФОНД | B4: 1027729004269 | C4: Действующая | D4: 7729418938 | E4: Москва | F4: Благотворительные фонды | G4: 0 - 5 | I4: 5000000 | K4: 4516000
A5: АВИАЦИОННО-КОСМИЧЕСКИЙ ФОНД, МОФ | B5: 1037746023061 | C5: Действующая | D5: 7730175408 | E5: Москва | F5: Общественные фонды | G5: 0 - 5
A6: АДВОКАТСКАЯ ИНИЦИАТИВА, ФОНД | B6: 1037739896226 | C6: Действующая | D6: 7704502779 | E6: Москва | F6: Общественные фонды | G6: 11 - 15 | H6: 51 - 100 | I6: 27002000 | J6: 25410000 | K6: 29355000 | L6: 24228000
A7: АДЫГИ ИМ. Ю.Х. КАЛМЫКОВА, ФОНД | B7: 1117799020283 | C7: Действующая | D7: 7701167716 | E7: Москва | F7: Фонды | G7: 0 - 5 | I7: 4280000 | J7: 2880000 | K7: 4122000 | L7: 2847000
A8: АЛЕКСАНДР, БФ | B8: 1127799000262 | C8: Действующая | D8: 7718747095 | E8: Москва | F8: Благотворительные фонды | G8: 0 - 5 | I8: 1661000 | J8: 1613000 | K8: 1674000 | L8: 1701000
A9: АЛИНЫ КАБАЕВОЙ, ФОНД | B9: 1087799027007 | C9: Действующая | D9: 7731282240 | E9: Москва | F9: Благотворительные фонды | G9: 0 - 5 | I9: 67000000 | J9: 146876000 | K9: 74958000 | L9: 107775000
A10: АЛФАВИТ, БЛАГОТВОРИТЕЛЬНЫЙ ФОНД | B10: 1047796688642 | C10: Действующая | D10: 7710556980 | E10: Москва | F10: Благотворительные фонды | G10: 0 - 5
A11: АЛЬФА-ШАНС, БФ | B11: 1137799022481 | C11: Действующая | D11: 7708241493 | E11: Москва | F11: Благотворительные фонды | G11: 0 - 5 | I11: 366217000 | J11: 362116000 | K11: 363962000 | L11: 362539000
A12: АНАЛИТИЧЕСКИЙ ЦЕНТР ФОРУМ, ФОНД | B12: 1107799031801 | C12: Действующая | D12: 7706414895 | E12: Москва | F12: Общественные фонды | G12: 51 - 100 | I12: 253031000 | J12: 150000000 | K12: 256576000 | L12: 211270000
A13: АНАСТАСИЯ, БЛАГОТВОРИТЕЛЬНЫЙ ФОНД | B13: 1132300004209 | C13: Действующая | D13: 2311981014 | E13: Москва | F13: Благотворительные фонды | G13: 0 - 5 | I13: 18169000 | J13: 23911000 | K13: 15809000 | L13: 21475000
A14: АНДРЕЯ БОГОЛЮБСКОГО, ФОНД | B14: 1117799010230 | C14: Действующая | D14: 7718746380 | E14: Москва | F14: Общественные фонды | G14: 0 - 5 | J14: 473000 | L14: 473000
A15: АПОСТОЛА АНДРЕЯ ПЕРВОЗВАННОГО; ФОНД АНДРЕЯ ПЕРВОЗВАННОГО, ФОНД | B15: 1027746000446 | C15: Действующая | D15: 7704243940 | E15: Москва | F15: Общественные фонды | G15: 11 - 15 | I15: 191006000 | J15: 195326000 | K15: 207475000 | L15: 165612000
A16: АРИФМЕТИКА ДОБРА, БФ | B16: 1147799003770 | C16: Действующая | D16: 7701093849 | E16: Москва | F16: Благотворительные фонды | G16: 51 - 100 | H16: 51 - 100 | I16: 128983000 | J16: 105573000 | K16: 95513000 | L16: 107906000
A17: АРТ ФЕСТИВАЛЬ-РОЗА ВЕТРОВ, ДБФ | B17: 1027739678724 | C17: Действующая | D17: 7734211777 | E17: Москва | F17: Благотворительные фонды | G17: 0 - 5 | J17: 35643000 | L17: 34247000
A18: АРТЕМИДА, БЛАГОТВОРИТЕЛЬНЫЙ ФОНД | B18: 1157700019916 | C18: Действующая | D18: 7708276104 | E18: Москва | F18: Благотворительные фонды | G18: 0 - 5 | I18: 16977000 | J18: 43816000 | K18: 20640000 | L18: 17161000
A19: АРТИСТ, БЛАГОТВОРИТЕЛЬНЫЙ ФОНД | B19: 1087799033630 | C19: Действующая | D19: 7705520001 | E19: Москва | F19: Благотворительные фонды | G19: 0 - 5 | I19: 78588000 | J19: 90809000 | K19: 76572000 | L19: 93156000
A20: АРТЭС, КБФ | B20: 1027739859663 | C20: Действующая | D20: 7705328820 | E20: Москва | F20: Благотворительные фонды | G20: 6 - 10 | I20: 381000 | J20: 857000 | K20: 3501000 | L20: 1441000
A21: БЕЗРАЗЛИЧИЯ. НЕТ, БФ | B21: 1157700020345 | C21: Действующая | D21: 9705056954 | E21: Москва | F21: Благотворительные фонды | G21: 0 - 5 | I21: 1684000 | J21: 734000 | K21: 81000 | L21: 2416000
A22: БЕЛЫЙ ИРИС, ФОНД | B22: 1167700056270 | C22: Действующая | D22: 7721486189 | E22: Москва | F22: Благотворительные фонды | G22: 0 - 5 | J22: 7821000 | L22: 6681000
A23: БЕЛЬКАНТО, БЛАГОТВОРИТЕЛЬНЫЙ ФОНД | B23: 1067746154904 | C23: Действующая | D23: 7703578750 | E23: Москва | F23: Благотворительные фонды | G23: 6 - 10 | I23: 9631000 | J23: 6580000 | K23: 24596000 | L23: 2387000
A24: БЕНЕФИС, ФОНД | B24: 1027700084829 | C24: Действующая | D24: 7707174999 | E24: Москва | F24: Благотворительные фонды | G24: 0 - 5 | I24: 153000 | J24: 786000 | K24: 123000 | L24: 822000
A25: БИМ, ФОНД | B25: 1027700592138 | C25: Действующая | D25: 7701274845 | E25: Москва | F25: Благотворительные фонды | G25: 0 - 5 | I25: 12211000 | J25: 12871000 | K25: 12285000 | L25: 12837000
A26: БИФ ПОМОГИ.ОРГ | B26: 1057748529684 | C26: Действующая | D26: 7702579448 | E26: Москва | F26: Благотворительные фонды | G26: 0 - 5 | J26: 150571000 | L26: 163859000
A27: БЛАГО, БФ | B27: 1027700129918 | C27: Действующая | D27: 7709223761 | E27: Москва | F27: Благотворительные фонды | G27: 0 - 5 | I27: 220873000 | K27: 218348000
A28: БЛАГОВЕСТ, РОФПСППМ | B28: 1037739344169 | C28: Действующая | D28: 7704200577 | E28: Москва | F28: Общественные фонды | G28: 0 - 5 | I28: 397000 | K28: 397000
A29: БЛАГОДАТЬ, БФ | B29: 1137799022580 | C29: Действующая | D29: 7704281713 | E29: Москва | F29: Благотворительные фонды | G29: 0 - 5
A30: БЛАГОЕ ДЕЛО В СТАРЫХ ЧЕРЕМУШКАХ, БФ | B30: 1107799031560 | C30: Действующая | D30: 7727002596 | E30: Москва | F30: Благотворительные фонды | G30: 11 - 15
A31: БЛАГОКРОВ, БФ | B31: 1147799006321 | C31: Действующая | D31: 7709473761 | E31: Москва | F31: Благотворительные фонды | G31: 0 - 5 | I31: 560000 | J31: 693000 | K31: 522000 | L31: 700000
A32: БЛАГОТВОРИТЕЛЬНЫЙ ФОНД ДМИТРИЯ КОРОБКОВА | B32: 1077799021871 | C32: Действующая | D32: 7704274226 | E32: Москва | F32: Благотворительные фонды | G32: 0 - 5 | I32: 3700000 | J32: 5970000 | K32: 3400000 | L32: 4861000
A33: БЛАГОТВОРИТЕЛЬНЫЙ ФОНД ЕЛЕНЫ ОБРАЗЦОВОЙ | B33: 1127799000515 | C33: Действующая | D33: 7710479630 | E33: Москва | F33: Благотворительные фонды | G33: 6 - 10 | J33: 71730000 | L33: 66625000
A34: БЛАГОТВОРИТЕЛЬНЫЙ ФОНД ЗАБОТА О БУДУЩЕМ, НКО | B34: 1127799013572 | C34: Действующая | D34: 7704279778 | E34: Москва | F34: Благотворительные фонды | G34: 0 - 5 | I34: 3226000 | J34: 2803000 | K34: 3248000 | L34: 2921000
A35: БЛАГОТВОРИТЕЛЬНЫЙ ФОНД ИМ. МЕЙЕРХОЛЬДА | B35: 1027739480614 | C35: Действующая | D35: 7710374290 | E35: Москва | F35: Благотворительные фонды | G35: 0 - 5 | I35: 4154000 | K35: 4154000
A36: БЛАГОТВОРИТЕЛЬНЫЙ ФОНД ИМЕНИ Д. ОЙСТРАХА, НО | B36: 1057746156456 | C36: Действующая | D36: 7703541239 | E36: Москва | F36: Благотворительные фонды | G36: 0 - 5
A37: БЛАГОТВОРИТЕЛЬНЫЙ ФОНД ИМЕНИ Е.И. РЕРИХ | B37: 1037700099161 | C37: Действующая | D37: 7705205585 | E37: Москва | F37: Благотворительные фонды | G37: 0 - 5 | I37: 4290000 | J37: 1719000 | K37: 2999000 | L37: 2861000
A38: БЛАГОТВОРИТЕЛЬНЫЙ ФОНД КУЛЬТУРЫ ИМ. Ю.Н. ДОЛЖИКОВА | B38: 1167700055808 | C38: Действующая | D38: 7714385292 | E38: Москва | F38: Благотворительные фонды | G38: 0 - 5 | I38: 275000 | J38: 2765000 | K38: 111000 | L38: 513000
A39: БЛАГОТВОРИТЕЛЬНЫЙ ФОНД ЛИГИ ЗДОРОВЬЯ НАЦИИ | B39: 1037789076490 | C39: Действующая | D39: 7706518132 | E39: Москва | F39: Благотворительные фонды | G39: 11 - 15 | I39: 13640000 | J39: 19783000 | K39: 2813000 | L39: 15449000
A40: БЛАГОТВОРИТЕЛЬНЫЙ ФОНД ЛИЦО РЕБЕНКА, НО | B40: 1037701912720 | C40: Действующая | D40: 7701340199 | E40: Москва | F40: Благотворительные фонды | G40: 0 - 5 | I40: 13220000 | J40: 14404000 | K40: 12976000 | L40: 13168000
...

Sheet report2
A1: ссч | B1: доходы | C1: расходы | D1: размер | E1: ссч(примерное) | F1: финансовый результат | G1: доход на сотрудника | H1: прибыль на сотрудника
A2: 0 - 5 | B2: 1533000 | C2: 1458000 | D2: =VLOOKUP(A2,Лист2!A:E,5,0) -> малые | E2: =VLOOKUP(A2,Лист2!A:E,4,0) -> 2.5 | F2: =B2-C2 -> 75000 | G2: =B2/E2 -> 613200 | H2: =F2/E2 -> 30000
A3: 11 - 15 | B3: 754602000 | C3: 641697000 | D3: =VLOOKUP(A3,Лист2!A:E,5,0) -> малые | E3: =VLOOKUP(A3,Лист2!A:E,4,0) -> 13 | F3: =B3-C3 -> 112905000 | G3: =B3/E3 -> 58046308 | H3: =F3/E3 -> 8685000
A4: 0 - 5 | B4: 5000000 | C4: 4516000 | D4: =VLOOKUP(A4,Лист2!A:E,5,0) -> малые | E4: =VLOOKUP(A4,Лист2!A:E,4,0) -> 2.5 | F4: =B4-C4 -> 484000 | G4: =B4/E4 -> 2000000 | H4: =F4/E4 -> 193600
A5: 11 - 15 | B5: 27002000 | C5: 29355000 | D5: =VLOOKUP(A5,Лист2!A:E,5,0) -> малые | E5: =VLOOKUP(A5,Лист2!A:E,4,0) -> 13 | F5: =B5-C5 -> -2353000 | G5: =B5/E5 -> 2077076.9 | H5: =F5/E5 -> -181000
A6: 0 - 5 | B6: 4280000 | C6: 4122000 | D6: =VLOOKUP(A6,Лист2!A:E,5,0) -> малые | E6: =VLOOKUP(A6,Лист2!A:E,4,0) -> 2.5 | F6: =B6-C6 -> 158000 | G6: =B6/E6 -> 1712000 | H6: =F6/E6 -> 63200
A7: 0 - 5 | B7: 1661000 | C7: 1674000 | D7: =VLOOKUP(A7,Лист2!A:E,5,0) -> малые | E7: =VLOOKUP(A7,Лист2!A:E,4,0) -> 2.5 | F7: =B7-C7 -> -13000 | G7: =B7/E7 -> 664400 | H7: =F7/E7 -> -5200
A8: 0 - 5 | B8: 67000000 | C8: 74958000 | D8: =VLOOKUP(A8,Лист2!A:E,5,0) -> малые | E8: =VLOOKUP(A8,Лист2!A:E,4,0) -> 2.5 | F8: =B8-C8 -> -7958000 | G8: =B8/E8 -> 26800000 | H8: =F8/E8 -> -3183200
A9: 0 - 5 | B9: 366217000 | C9: 363962000 | D9: =VLOOKUP(A9,Лист2!A:E,5,0) -> малые | E9: =VLOOKUP(A9,Лист2!A:E,4,0) -> 2.5 | F9: =B9-C9 -> 2255000 | G9: =B9/E9 -> 146486800 | H9: =F9/E9 -> 902000
A10: 51 - 100 | B10: 253031000 | C10: 256576000 | D10: =VLOOKUP(A10,Лист2!A:E,5,0) -> средние | E10: =VLOOKUP(A10,Лист2!A:E,4,0) -> 75.5 | F10: =B10-C10 -> -3545000 | G10: =B10/E10 -> 3351404 | H10: =F10/E10 -> -46953.642
A11: 0 - 5 | B11: 18169000 | C11: 15809000 | D11: =VLOOKUP(A11,Лист2!A:E,5,0) -> малые | E11: =VLOOKUP(A11,Лист2!A:E,4,0) -> 2.5 | F11: =B11-C11 -> 2360000 | G11: =B11/E11 -> 7267600 | H11: =F11/E11 -> 944000
A12: 11 - 15 | B12: 191006000 | C12: 207475000 | D12: =VLOOKUP(A12,Лист2!A:E,5,0) -> малые | E12: =VLOOKUP(A12,Лист2!A:E,4,0) -> 13 | F12: =B12-C12 -> -16469000 | G12: =B12/E12 -> 14692769 | H12: =F12/E12 -> -1266846.2
A13: 51 - 100 | B13: 128983000 | C13: 95513000 | D13: =VLOOKUP(A13,Лист2!A:E,5,0) -> средние | E13: =VLOOKUP(A13,Лист2!A:E,4,0) -> 75.5 | F13: =B13-C13 -> 33470000 | G13: =B13/E13 -> 1708384.1 | H13: =F13/E13 -> 443311.26
... A1771: 201 - 250 | B1771: 995636000 | C1771: 985164000 | D1771: =VLOOKUP(A1771,Лист2!A:E,5,0) -> крупные | E1771: =VLOOKUP(A1771,Лист2!A:E,4,0) -> 225.5 | F1771: =B1771-C1771 -> 10472000 | G1771: =B1771/E1771 -> 4415237.3 | H1771: =F1771/E1771 -> 46439.024

Sheet report3
A1: ссч | B1: доходы | C1: расходы | D1: размер | E1: ссч(примерное) | F1: финансовый результат | G1: доход на сотрудника | H1: прибыль на сотрудника
A2: 0 - 5 | B2: 1533000 | C2: 1458000 | D2: =VLOOKUP(A2,Лист2!A:E,5,0) -> малые | E2: =VLOOKUP(A2,Лист2!A:E,4,0) -> 2.5 | F2: =B2-C2 -> 75000 | G2: =B2/E2 -> 613200 | H2: =F2/E2 -> 30000
A3: 11 - 15 | B3: 754602000 | C3: 641697000 | D3: =VLOOKUP(A3,Лист2!A:E,5,0) -> малые | E3: =VLOOKUP(A3,Лист2!A:E,4,0) -> 13 | F3: =B3-C3 -> 112905000 | G3: =B3/E3 -> 58046308 | H3: =F3/E3 -> 8685000
A4: 0 - 5 | B4: 5000000 | C4: 4516000 | D4: =VLOOKUP(A4,Лист2!A:E,5,0) -> малые | E4: =VLOOKUP(A4,Лист2!A:E,4,0) -> 2.5 | F4: =B4-C4 -> 484000 | G4: =B4/E4 -> 2000000 | H4: =F4/E4 -> 193600
A5: 11 - 15 | B5: 27002000 | C5: 29355000 | D5: =VLOOKUP(A5,Лист2!A:E,5,0) -> малые | E5: =VLOOKUP(A5,Лист2!A:E,4,0) -> 13 | F5: =B5-C5 -> -2353000 | G5: =B5/E5 -> 2077076.9 | H5: =F5/E5 -> -181000
A6: 0 - 5 | B6: 4280000 | C6: 4122000 | D6: =VLOOKUP(A6,Лист2!A:E,5,0) -> малые | E6: =VLOOKUP(A6,Лист2!A:E,4,0) -> 2.5 | F6: =B6-C6 -> 158000 | G6: =B6/E6 -> 1712000 | H6: =F6/E6 -> 63200
A7: 0 - 5 | B7: 1661000 | C7: 1674000 | D7: =VLOOKUP(A7,Лист2!A:E,5,0) -> малые | E7: =VLOOKUP(A7,Лист2!A:E,4,0) -> 2.5 | F7: =B7-C7 -> -13000 | G7: =B7/E7 -> 664400 | H7: =F7/E7 -> -5200
A8: 0 - 5 | B8: 67000000 | C8: 74958000 | D8: =VLOOKUP(A8,Лист2!A:E,5,0) -> малые | E8: =VLOOKUP(A8,Лист2!A:E,4,0) -> 2.5 | F8: =B8-C8 -> -7958000 | G8: =B8/E8 -> 26800000 | H8: =F8/E8 -> -3183200
A9: 0 - 5 | B9: 366217000 | C9: 363962000 | D9: =VLOOKUP(A9,Лист2!A:E,5,0) -> малые | E9: =VLOOKUP(A9,Лист2!A:E,4,0) -> 2.5 | F9: =B9-C9 -> 2255000 | G9: =B9/E9 -> 146486800 | H9: =F9/E9 -> 902000
A10: 51 - 100 | B10: 253031000 | C10: 256576000 | D10: =VLOOKUP(A10,Лист2!A:E,5,0) -> средние | E10: =VLOOKUP(A10,Лист2!A:E,4,0) -> 75.5 | F10: =B10-C10 -> -3545000 | G10: =B10/E10 -> 3351404 | H10: =F10/E10 -> -46953.642
A11: 0 - 5 | B11: 18169000 | C11: 15809000 | D11: =VLOOKUP(A11,Лист2!A:E,5,0) -> малые | E11: =VLOOKUP(A11,Лист2!A:E,4,0) -> 2.5 | F11: =B11-C11 -> 2360000 | G11: =B11/E11 -> 7267600 | H11: =F11/E11 -> 944000
A12: 11 - 15 | B12: 191006000 | C12: 207475000 | D12: =VLOOKUP(A12,Лист2!A:E,5,0) -> малые | E12: =VLOOKUP(A12,Лист2!A:E,4,0) -> 13 | F12: =B12-C12 -> -16469000 | G12: =B12/E12 -> 14692769 | H12: =F12/E12 -> -1266846.2
A13: 51 - 100 | B13: 128983000 | C13: 95513000 | D13: =VLOOKUP(A13,Лист2!A:E,5,0) -> средние | E13: =VLOOKUP(A13,Лист2!A:E,4,0) -> 75.5 | F13: =B13-C13 -> 33470000 | G13: =B13/E13 -> 1708384.1 | H13: =F13/E13 -> 443311.26
... A1720: 0 - 5 | B1720: 10000 | C1720: 10000 | D1720: =VLOOKUP(A1720,Лист2!A:E,5,0) -> малые | E1720: =VLOOKUP(A1720,Лист2!A:E,4,0) -> 2.5 | F1720: =B1720-C1720 -> 0 | G1720: =B1720/E1720 -> 4000 | H1720: =F1720/E1720 -> 0

Sheet report4
A1: регион | B1: ссч | C1: доходы | D1: расходы | E1: размер | F1: ссч(примерное) | G1: финансовый результат | H1: доход на сотрудника | I1: прибыль на сотрудника
A2: Москва | B2: 0 - 5 | C2: 1533000 | D2: 1458000 | E2: малые | F2: 2.5 | G2: 75000 | H2: 613200 | I2: 30000
A3: Москва | B3: 11 - 15 | C3: 754602000 | D3: 641697000 | E3: малые | F3: 13 | G3: 112905000 | H3: 58046308 | I3: 8685000
A4: Москва | B4: 0 - 5 | C4: 5000000 | D4: 4516000 | E4: малые | F4: 2.5 | G4: 484000 | H4: 2000000 | I4: 193600
A5: Москва | B5: 11 - 15 | C5: 27002000 | D5: 29355000 | E5: малые | F5: 13 | G5: -2353000 | H5: 2077076.9 | I5: -181000
A6: Москва | B6: 0 - 5 | C6: 4280000 | D6: 4122000 | E6: малые | F6: 2.5 | G6: 158000 | H6: 1712000 | I6: 63200
A7: Москва | B7: 0 - 5 | C7: 1661000 | D7: 1674000 | E7: малые | F7: 2.5 | G7: -13000 | H7: 664400 | I7: -5200
A8: Москва | B8: 0 - 5 | C8: 67000000 | D8: 74958000 | E8: малые | F8: 2.5 | G8: -7958000 | H8: 26800000 | I8: -3183200
A9: Москва | B9: 0 - 5 | C9: 366217000 | D9: 363962000 | E9: малые | F9: 2.5 | G9: 2255000 | H9: 146486800 | I9: 902000
A10: Москва | B10: 51 - 100 | C10: 253031000 | D10: 256576000 | E10: средние | F10: 75.5 | G10: -3545000 | H10: 3351404 | I10: -46953.642
A11: Москва | B11: 0 - 5 | C11: 18169000 | D11: 15809000 | E11: малые | F11: 2.5 | G11: 2360000 | H11: 7267600 | I11: 944000
A12: Москва | B12: 11 - 15 | C12: 191006000 | D12: 207475000 | E12: малые | F12: 13 | G12: -16469000 | H12: 14692769 | I12: -1266846.2
A13: Москва | B13: 51 - 100 | C13: 128983000 | D13: 95513000 | E13: средние | F13: 75.5 | G13: 33470000 | H13: 1708384.1 | I13: 443311.26
... A1771: Красноярский край | B1771: 201 - 250 | C1771: 995636000 | D1771: 985164000 | E1771: крупные | F1771: 225.5 | G1771: 10472000 | H1771: 4415237.3 | I1771: 46439.024

Sheet report5
A1: Организационно-правовая форма | B1: 2017, Среднесписочная численность работников | C1: 2017, Всего поступило средств, RUB | D1: 2017, Всего использовано средств, RUB | E1: размер | F1: ссч примерное | G1: финансовый результат | H1: доход на сотрудника | I1: прибыль на сотрудника
A2: Благотворительные фонды | B2: 0 - 5 | C2: 1533000 | D2: 1458000 | E2: =VLOOKUP(B2,Лист2!A:E,5,0) -> малые | F2: =VLOOKUP(B2,Лист2!A:E,4,0) -> 2.5 | G2: =C2-D2 -> 75000 | H2: =C2/F2 -> 613200 | I2: =G2/F2 -> 30000
A3: Благотворительные фонды | B3: 11 - 15 | C3: 754602000 | D3: 641697000 | E3: =VLOOKUP(B3,Лист2!A:E,5,0) -> малые | F3: =VLOOKUP(B3,Лист2!A:E,4,0) -> 13 | G3: =C3-D3 -> 112905000 | H3: =C3/F3 -> 58046308 | I3: =G3/F3 -> 8685000
A4: Благотворительные фонды | B4: 0 - 5 | C4: 5000000 | D4: 4516000 | E4: =VLOOKUP(B4,Лист2!A:E,5,0) -> малые | F4: =VLOOKUP(B4,Лист2!A:E,4,0) -> 2.5 | G4: =C4-D4 -> 484000 | H4: =C4/F4 -> 2000000 | I4: =G4/F4 -> 193600
A5: Общественные фонды | B5: 11 - 15 | C5: 27002000 | D5: 29355000 | E5: =VLOOKUP(B5,Лист2!A:E,5,0) -> малые | F5: =VLOOKUP(B5,Лист2!A:E,4,0) -> 13 | G5: =C5-D5 -> -2353000 | H5: =C5/F5 -> 2077076.9 | I5: =G5/F5 -> -181000
A6: Фонды | B6: 0 - 5 | C6: 4280000 | D6: 4122000 | E6: =VLOOKUP(B6,Лист2!A:E,5,0) -> малые | F6: =VLOOKUP(B6,Лист2!A:E,4,0) -> 2.5 | G6: =C6-D6 -> 158000 | H6: =C6/F6 -> 1712000 | I6: =G6/F6 -> 63200
A7: Благотворительные фонды | B7: 0 - 5 | C7: 1661000 | D7: 1674000 | E7: =VLOOKUP(B7,Лист2!A:E,5,0) -> малые | F7: =VLOOKUP(B7,Лист2!A:E,4,0) -> 2.5 | G7: =C7-D7 -> -13000 | H7: =C7/F7 -> 664400 | I7: =G7/F7 -> -5200
A8: Благотворительные фонды | B8: 0 - 5 | C8: 67000000 | D8: 74958000 | E8: =VLOOKUP(B8,Лист2!A:E,5,0) -> малые | F8: =VLOOKUP(B8,Лист2!A:E,4,0) -> 2.5 | G8: =C8-D8 -> -7958000 | H8: =C8/F8 -> 26800000 | I8: =G8/F8 -> -3183200
A9: Благотворительные фонды | B9: 0 - 5 | C9: 366217000 | D9: 363962000 | E9: =VLOOKUP(B9,Лист2!A:E,5,0) -> малые | F9: =VLOOKUP(B9,Лист2!A:E,4,0) -> 2.5 | G9: =C9-D9 -> 2255000 | H9: =C9/F9 -> 146486800 | I9: =G9/F9 -> 902000
A10: Общественные фонды | B10: 51 - 100 | C10: 253031000 | D10: 256576000 | E10: =VLOOKUP(B10,Лист2!A:E,5,0) -> средние | F10: =VLOOKUP(B10,Лист2!A:E,4,0) -> 75.5 | G10: =C10-D10 -> -3545000 | H10: =C10/F10 -> 3351404 | I10: =G10/F10 -> -46953.642
A11: Благотворительные фонды | B11: 0 - 5 | C11: 18169000 | D11: 15809000 | E11: =VLOOKUP(B11,Лист2!A:E,5,0) -> малые | F11: =VLOOKUP(B11,Лист2!A:E,4,0) -> 2.5 | G11: =C11-D11 -> 2360000 | H11: =C11/F11 -> 7267600 | I11: =G11/F11 -> 944000
A12: Общественные фонды | B12: 11 - 15 | C12: 191006000 | D12: 207475000 | E12: =VLOOKUP(B12,Лист2!A:E,5,0) -> малые | F12: =VLOOKUP(B12,Лист2!A:E,4,0) -> 13 | G12: =C12-D12 -> -16469000 | H12: =C12/F12 -> 14692769 | I12: =G12/F12 -> -1266846.2
A13: Благотворительные фонды | B13: 51 - 100 | C13: 128983000 | D13: 95513000 | E13: =VLOOKUP(B13,Лист2!A:E,5,0) -> средние | F13: =VLOOKUP(B13,Лист2!A:E,4,0) -> 75.5 | G13: =C13-D13 -> 33470000 | H13: =C13/F13 -> 1708384.1 | I13: =G13/F13 -> 443311.26
... A1771: Благотворительные фонды | B1771: 201 - 250 | C1771: 995636000 | D1771: 985164000 | E1771: =VLOOKUP(B1771,Лист2!A:E,5,0) -> крупные | F1771: =VLOOKUP(B1771,Лист2!A:E,4,0) -> 225.5 | G1771: =C1771-D1771 -> 10472000 | H1771: =C1771/F1771 -> 4415237.3 | I1771: =G1771/F1771 -> 46439.024

Sheet Лист2
A1: 0 - 5 | B1: 0 | C1: 5 | D1: =AVERAGE(B1:C1) -> 2.5 | E1: малые | L1: Благотворительные фонды
A2: 6 - 10 | B2: 6 | C2: 10 | D2: =AVERAGE(B2:C2) -> 8 | E2: малые | L2: Общественные фонды
A3: 11 - 15 | B3: 11 | C3: 15 | D3: =AVERAGE(B3:C3) -> 13 | E3: малые | L3: Фонды
A4: 51 - 100 | B4: 51 | C4: 100 | D4: =AVERAGE(B4:C4) -> 75.5 | E4: средние | L4: Экологические фонды
A5: 101 - 150 | B5: 101 | C5: 150 | D5: =AVERAGE(B5:C5) -> 125.5 | E5: средние | L5: Общественные организации
A6: 151 - 200 | B6: 151 | C6: 200 | D6: =AVERAGE(B6:C6) -> 175.5 | E6: средние
A7: 201 - 250 | B7: 201 | C7: 250 | D7: =AVERAGE(B7:C7) -> 225.5 | E7: крупные
A8: 251 - 500 | B8: 251 | C8: 500 | D8: =AVERAGE(B8:C8) -> 375.5 | E8: крупные
A9: 501 - 1 000 | B9: 501 | C9: 1000 | D9: =AVERAGE(B9:C9) -> 750.5 | E9: крупные
